<?xml version="1.0"?>
<robot xmlns:xacro="http://www.ros.org/wiki/xacro" name="diablo_pluspro">
  <xacro:macro name="description">
    <link name="base_link">
      <inertial>
        <origin xyz="0.02817 -0.0049865 0.16853" rpy="0 0 0" />
        <mass value="8.53" />
        <inertia ixx="0.8371974" ixy="-0.06254957" ixz="-0.01618499" iyy="0.8708397" iyz="0.003006719" izz="0.3425067" />
      </inertial>
      <visual>
        <origin xyz="0 0 0" rpy="0 0 0" />
        <geometry>
          <mesh filename="file://$(find tita_description)/diablo_plus_pro/meshes/base_link.STL" />
        </geometry>
        <material name="white"/>
      </visual>
      <collision>
        <origin xyz="0 0 0" rpy="0 0 0" />
        <geometry>
          <mesh filename="file://$(find tita_description)/diablo_plus_pro/meshes/base_link.STL" />
        </geometry>
      </collision>
    </link>

    <link name="imu_link">
      <inertial>
        <mass value="0.001"/>
        <origin rpy="0 0 0" xyz="0 0 0"/>
        <inertia ixx="0.0001" ixy="0" ixz="0" iyy="0.0001" iyz="0" izz="0.0001"/>
      </inertial>
      <visual>
        <origin rpy="0 0 0" xyz="0 0 0"/>
        <geometry>
          <box size="0.001 0.001 0.001"/>
        </geometry>
        <material name="red"/>
      </visual>
      <collision>
        <origin rpy="0 0 0" xyz="0 0 0"/>
        <geometry>
          <box size=".001 .001 .001"/>
        </geometry>
      </collision>
    </link>
    <joint name="imu_joint" type="fixed">
      <parent link="base_link"/>
      <child link="imu_link"/>
      <origin rpy="0 0 0" xyz="0 0 0"/>
    </joint>

   <link name="left_hip_link">
      <inertial>
        <origin xyz="-0.02147 0.083955 -0.036946" rpy="0 0 0" />
        <mass value="5.1" />
        <inertia ixx="0.01137421" ixy="0.00070511460" ixz="0.00124554" iyy="0.0082006541" iyz="0.0029798900" izz="0.0060506903" />
      </inertial>
      <visual>
        <origin xyz="0 0 0" rpy="0 0 0" />
        <geometry>
          <mesh filename="file://$(find tita_description)/diablo_plus_pro/meshes/left_hip_link.STL" />
        </geometry>
        <material name="white"/>
      </visual>
      <collision>
        <origin xyz="0 0 0" rpy="0 0 0" />
        <geometry>
          <mesh filename="file://$(find tita_description)/diablo_plus_pro/meshes/left_hip_link.STL" />
        </geometry>
      </collision>
    </link>
    <joint name="left_hip_joint" type="revolute">
      <origin xyz="0 0.0428 0.075997" rpy="0 0 0" />
      <parent link="base_link" />
      <child link="left_hip_link" />
      <axis xyz="0 1 0" />
      <limit lower="-1.0" upper="1.2" effort="80" velocity="15" />
    </joint>

    <link name="left_knee_link">
      <inertial>
        <origin xyz="0.091371 -0.0059746 0.042483" rpy="0 0 0" />
        <mass value="2.0" />
        <inertia ixx="0.0044665319" ixy="1.2345077E-05" ixz="-0.00023975799" iyy="0.0046256777" iyz="-0.00022848392" izz="0.0002702575" />
      </inertial>
      <visual>
        <origin xyz="0 0 0" rpy="0 0 0" />
        <geometry>
          <mesh filename="file://$(find tita_description)/diablo_plus_pro/meshes/left_knee_link.STL" />
        </geometry>
        <material name="white"/>
      </visual>
      <collision>
        <origin xyz="0 0 0" rpy="0 0 0" />
        <geometry>
          <mesh filename="file://$(find tita_description)/diablo_plus_pro/meshes/left_knee_link.STL" />
        </geometry>
      </collision>
    </link>
    <joint name="left_knee_joint" type="revolute">
      <origin xyz="-0.088027 0.11148 -0.17958" rpy="0 0 0" />
      <parent link="left_hip_link" />
      <child link="left_knee_link" />
      <axis xyz="0 1 0" />
      <limit lower="0" upper="1.2" effort="80" velocity="15" />
    </joint>

    <link name="left_wheel_link">
      <inertial>
        <origin xyz="-2.0379E-06 0.019153 -4.2928E-07" rpy="0 0 0" />
        <mass value="2.0" />
        <inertia ixx="0.013847" ixy="-1.0562E-07" ixz="4.372E-10" iyy="0.027351" iyz="-3.2677E-08" izz="0.013847" />
      </inertial>
      <visual>
        <origin xyz="0 0 0" rpy="0 0 0" />
        <geometry>
          <mesh filename="file://$(find tita_description)/diablo_plus_pro/meshes/left_wheel_link.STL" />
        </geometry>
        <material name="orange"/>
      </visual>
      <collision>
        <origin xyz="0 0.02 0" rpy="1.5707963 0 0" />
        <geometry>
          <cylinder radius="0.16" length="0.035"/>
        </geometry>
      </collision>
    </link>
    <joint name="left_wheel_joint" type="revolute">
      <origin xyz="0.17064 0.02266 0.10432" rpy="0 0 0" />
      <parent link="left_knee_link" />
      <child link="left_wheel_link" />
      <axis xyz="0 1 0" />
      <limit lower="-1000000" upper="1000000" effort="20" velocity="30" />
    </joint>

    <link name="right_hip_link">
      <inertial>
        <origin xyz="-0.02147 -0.083955 -0.036946" rpy="0 0 0" />
        <mass value="5.1" />
        <inertia ixx="0.01137421" ixy="0.00070511460" ixz="0.00124554" iyy="0.0082006541" iyz="0.0029798900" izz="0.0060506903" />
      </inertial>
      <visual>
        <origin xyz="0 0 0" rpy="0 0 0" />
        <geometry>
          <mesh filename="file://$(find tita_description)/diablo_plus_pro/meshes/right_hip_link.STL" />
        </geometry>
        <material name="white"/>
      </visual>
      <collision>
        <origin xyz="0 0 0" rpy="0 0 0" />
        <geometry>
          <mesh filename="file://$(find tita_description)/diablo_plus_pro/meshes/right_hip_link.STL" />
        </geometry>
      </collision>
    </link>
    <joint name="right_hip_joint" type="revolute">
      <origin xyz="0 -0.0528 0.075997" rpy="0 0 0" />
      <parent link="base_link" />
      <child link="right_hip_link" />
      <axis xyz="0 1 0" />
      <limit lower="-1.0" upper="1.2" effort="80" velocity="15" />
    </joint>

    <link name="right_knee_link">
      <inertial>
        <origin xyz="0.091173 -0.0018038 0.042402" rpy="0 0 0" />
        <mass value="2.17" />
        <inertia ixx="0.0044665319" ixy="1.2345077E-05" ixz="-0.00023975799" iyy="0.0046256777" iyz="-0.00022848392" izz="0.0002702575" />
      </inertial>
      <visual>
        <origin xyz="0 0 0" rpy="0 0 0" />
        <geometry>
          <mesh filename="file://$(find tita_description)/diablo_plus_pro/meshes/right_knee_link.STL" />
        </geometry>
        <material name="white"/>
      </visual>
      <collision>
        <origin xyz="0 0 0" rpy="0 0 0" />
        <geometry>
          <mesh filename="file://$(find tita_description)/diablo_plus_pro/meshes/right_knee_link.STL" />
        </geometry>
      </collision>
    </link>
    <joint name="right_knee_joint" type="revolute">
      <origin xyz="-0.088029 -0.10364 -0.17958" rpy="0 0 0" />
      <parent link="right_hip_link" />
      <child link="right_knee_link" />
      <axis xyz="0 1 0" />
      <limit lower="0" upper="1.2" effort="80" velocity="15" />
    </joint>

    <link name="right_wheel_link">
      <inertial>
        <origin xyz="7.6456E-08 -0.019153 -2.0799E-06" rpy="0 0 0" />
        <mass value="2.0" />
        <inertia ixx="0.013847" ixy="4.8112E-09" ixz="-1.9773E-09" iyy="0.027351" iyz="1.0933E-07" izz="0.013847" />
      </inertial>
      <visual>
        <origin xyz="0 0 0" rpy="0 0 0" />
        <geometry>
          <mesh filename="file://$(find tita_description)/diablo_plus_pro/meshes/right_wheel_link.STL" />
        </geometry>
        <material name="orange"/>
      </visual>
      <collision>
        <origin xyz="0 -0.02 0" rpy="1.5707963 0 0" />
        <geometry>
          <cylinder radius="0.16" length="0.035"/>
        </geometry>
      </collision>
    </link>
    <joint name="right_wheel_joint" type="revolute">
      <origin xyz="0.17064 -0.03046 0.10432" rpy="0 0 0" />
      <parent link="right_knee_link" />
      <child link="right_wheel_link" />
      <axis xyz="0 1 0" />
      <limit lower="-1000000" upper="1000000" effort="20" velocity="30" />
    </joint>
    
  </xacro:macro>
</robot>